Workbook

Sheet APAC + JP Activation Plan
B2: Persuasion | C2: GEO | D2: Programmatic (TTD) | E2: Social Awareness | F2: Lead Gen | G2: Total Regional | H2: Estimated Total Leads | I2: CPL
C3: APAC | D3: ='APAC Activation Plan'!D20 -> 43557.56 | E3: ='APAC Activation Plan'!E20 -> 23250 | F3: ='APAC Activation Plan'!F20 -> 37772.44 | G3: ='APAC Activation Plan'!G20 -> 104580 | H3: 210 | I3: 180
C4: Japan | D4: ='JP Activation Plan'!D13 -> 4067 | E4: ='JP Activation Plan'!E13 -> 0 | F4: ='JP Activation Plan'!F13 -> 7553 | G4: ='JP Activation Plan'!G13 -> 11620 | H4: 42 | I4: 180
B6: Precision | C6: Geo | D6: 2 Touch MQLs | E6: CPL | F6: Estimated Total Leads | G6: Total Regional
C7: APAC | D7: 94122 | E7: 60 | F7: 1569 | G7: 94122
C8: Japan | D8: 10458 | E8: 60 | F8: 174 | G8: 10458
B10: Conversion | C10: Geo | D10: 2 Touch MQLs + Pulse Survey | E10: CPL | F10: Estimated Total Leads | G10: Total Regional
C11: APAC | D11: 31374 | E11: 97 | F11: 323 | G11: 31374
C12: Japan | D12: 3486 | E12: 97 | F12: 36 | G12: 3486
C14: Geo | D14: 2 Touch MQLs + Qualification Questions | E14: CPL | F14: Estimated Total Leads | G14: Total Regional
C15: APAC | D15: 31374 | E15: 102 | F15: 308 | G15: 31374
C16: Japan | D16: 3486 | E16: 102 | F16: 34 | G16: 3486
B18: Total Media Spend USD | G18: =ROUND(G3+G4+G7+G8+G11+G12+G15+G16,0) -> 290500
B19: 7% Media Planning & Buying | G19: =ROUND(G22*0.07,0) -> 24500
B20: 6% Media Reporting & Optimisation | G20: =ROUND(G22*0.06,0) -> 21000
B21: 4% Technology & Lead Management: | G21: =ROUND(G22*0.04,0) -> 14000
B22: Total Program Budget USD | G22: =ROUND(G18/(1-0.07-0.06-0.04),0) -> 350000
B25: Persuasion : Paid Media Lead Gen Goals (Q3 FY26)
B26: Region | C26: Platform | D26: Lead-gen Budget | E26: Planning CPL | F26: Commit Leads
B27: ANZ | C27: LinkedIn | D27: 18051 | E27: 301 | F27: 60
B28: ASEAN | C28: LinkedIn | D28: 10066 | E28: 126 | F28: 80
B29: SAARC India | C29: LinkedIn | D29: 6798 | E29: 115 | F29: 59
B30: GCR-HK | C30: LinkedIn | D30: 2858 | E30: 260 | F30: 11
B31: GCR-CN | C31: TTD | D31: 0 | E31: n/a | F31: 0
B32: GCR-TW | C32: TTD | D32: 0 | E32: n/a | F32: 0
B33: KR | C33: TTD | D33: 0 | E33: n/a | F33: 0
B34: Japan | C34: YouTube | D34: 7553 | E34: 180 | F34: 42
B35: APAC subtotal (LinkedIn) | D35: 37772 | E35: 180 | F35: 210
B36: Total incl Japan | D36: 37772 | E36: 180 | F36: 210

Sheet APAC Activation Plan
B2: Client | C2: Cloudflare
B3: Campaign | C3: Q3 FY26 Core Demand Generation : APAC
B4: Quarter | C4: Q3 FY26
B5: Start date | C5: 2026-07-01
B6: End date | C6: 2026-09-30
B7: Duration (days) | C7: 92
B8: APAC budget | C8: $104,580.00
B10: REGIONAL BUDGET SUMMARY (APAC)
B11: GEO | C11: % of APAC | D11: Programmatic (TTD) | E11: Social Awareness (LinkedIn) | F11: Lead Gen (LinkedIn / YouTube) | G11: Total Regional | H11: Channels in scope
B12: ANZ | C12: =G12/$G$20 -> 0.5 | D12: 15739.31 | E12: 18500 | F12: 18050.69 | G12: =SUM(D12:F12) -> 52290 | H12: LinkedIn + TTD
B13: ASEAN | C13: =G13/$G$20 -> 0.19 | D13: 6954.56 | E13: 2850 | F13: 10065.64 | G13: =SUM(D13:F13) -> 19870.2 | H13: LinkedIn + TTD
B14: SAARC (IN) | C14: =G14/$G$20 -> 0.1 | D14: 3660.3 | E14: 0 | F14: 6797.7 | G14: =SUM(D14:F14) -> 10458 | H14: LinkedIn + TTD
B15: GCR - CN | C15: =G15/$G$20 -> 0.035 | D15: 3660.3 | E15: 0 | F15: 0 | G15: =SUM(D15:F15) -> 3660.3 | H15: TTD only (double-gated)
B16: GCR - HK | C16: =G16/$G$20 -> 0.07 | D16: 2562.19 | E16: 1900 | F16: 2858.41 | G16: =SUM(D16:F16) -> 7320.6 | H16: LinkedIn + TTD
B17: GCR - TW | C17: =G17/$G$20 -> 0.035 | D17: 3660.3 | E17: 0 | F17: 0 | G17: =SUM(D17:F17) -> 3660.3 | H17: TTD only
B18: KR | C18: =G18/$G$20 -> 0.07 | D18: 7320.6 | E18: 0 | F18: 0 | G18: =SUM(D18:F18) -> 7320.6 | H18: TTD only
B20: APAC TOTAL | C20: =SUM(C12:C19) -> 1 | D20: =SUM(D12:D19) -> 43557.56 | E20: =SUM(E12:E19) -> 23250 | F20: =SUM(F12:F19) -> 37772.44 | G20: =SUM(G12:G19) -> 104580
B21: SAME BUDGETS, CUT BY ACTUAL PLATFORM (TTD / LinkedIn)
B22: The table above shows budget through CF's channel structure (Prog Awareness / Social Awareness / Social Lead Gen). This table below shows the same dollars by actual platform. TTD is higher than the LinkedIn column in the TTD-only markets because the CN, TW and KR budgets all run on TTD, plus the CN/TW/KR reallocated social (no social platforms in scope) get reallocated to TTD.
B23: Platform | C23: Budget USD | D23: % of APAC | F23: Source breakdown
B24: LinkedIn | C24: 61022.44 | D24: =C24/$C$27 -> 0.5835001 | F24: LinkedIn awareness + lead gen across ANZ, ASEAN, India and HK
B25: TTD | C25: 43557.56 | D25: =C25/$C$27 -> 0.4164999 | F25: All programmatic across CN, TW and KR (TTD-only) plus a retargeting line in every market
B26: Reddit | C26: 0 | D26: =C26/$C$27 -> 0 | F26: Dropped in Q3 (K2). Its ANZ budget moved to LinkedIn lead gen
B27: APAC TOTAL | C27: =SUM(C24:C26) -> 104580 | D27: =SUM(D24:D26) -> 1 | F27: Matches Regional Total of $104,580 (same dollars, different view)
B28: See Platform Allocation sheet for the full reconciliation table.
B32: PROGRAM SCHEDULE : APAC
B33: GEO | C33: Phase | D33: Audience | E33: Platform | F33: Targeting | G33: Weight | H33: Budget USD | I33: CPM | J33: CPC | K33: CTR | L33: Impressions | M33: Clicks | N33: Cost Type
B34: ANZ : $52,290.00 (50.0% of APAC) : LinkedIn (PEYC) + TTD : RIG folded into ANZ LinkedIn, now the PEYC campaign | G34: Regional total → | H34: 52290
B35: ANZ | C35: Programmatic AWR | D35: Decision-makers at TAL accounts (AU + NZ) | E35: TTD | F35: B2Beacon : ABM, seniority and industry baked in on the Bombora push | G35: 0.0669 | H35: 3500 | I35: 18 | J35: =I35/1000/K35 -> 22.5 | K35: 0.0008 | L35: =H35/I35*1000 -> 194444.44 | M35: =L35*K35 -> 155.55556 | N35: CPM
B36: ANZ | C36: Programmatic AWR | D36: Decision-makers in target industries, scaled reach (AU + NZ) | E36: TTD | F36: Premium publisher whitelist + 3PA decision-makers + 3PA target industries | G36: 0.0669 | H36: 3500 | I36: 16 | J36: =I36/1000/K36 -> 20 | K36: 0.0008 | L36: =H36/I36*1000 -> 218750 | M36: =L36*K36 -> 175 | N36: CPM
B37: ANZ | C37: Programmatic RTG | D37: Site visitors, no additional filters (AU + NZ) | E37: TTD | F37: Retargeting : Universal Pixel site-visit pool, no seniority or industry filter | G37: 0.1671 | H37: 8739.31 | I37: 14 | J37: =I37/1000/K37 -> 7.7777778 | K37: 0.0018 | L37: =H37/I37*1000 -> 624236.43 | M37: =L37*K37 -> 1123.6256 | N37: CPM
B38: ANZ | C38: Social Lead Gen | D38: Warm retargeting pools: website all-visitors, AI-security, LP and PEYC-LP 180d, image-clickers and video-viewers 365d, LGF-openers 180d (AU + NZ) | E38: LinkedIn | F38: MOFU Document with LGF (CONSID-DOC) : warm retargeting | G38: 0.2878 | H38: 15050.69 | I38: 78 | J38: =I38/1000/K38 -> 20.526316 | K38: 0.0038 | L38: =H38/I38*1000 -> 192957.56 | M38: =L38*K38 -> 733.23874 | N38: CPM
B39: ANZ | C39: Social AWR | D39: Cold lists plus seniority and function (AU + NZ) | E39: LinkedIn | F39: TOFU Carousel (AWR-CRSL) : website visits | G39: 0.1147 | H39: 6000 | I39: 65 | J39: =I39/1000/K39 -> 16.666667 | K39: 0.0039 | L39: =H39/I39*1000 -> 92307.692 | M39: =L39*K39 -> 360 | N39: CPM
B40: ANZ | C40: Social AWR | D40: Cold lists plus seniority and function, tighter frequency cap (AU + NZ) | E40: LinkedIn | F40: TOFU Video (AWR-VID) : video views, frequency capped | G40: 0.0861 | H40: 4500 | I40: 16 | J40: =I40/1000/K40 -> 22.857143 | K40: 0.0007 | L40: =H40/I40*1000 -> 281250 | M40: =L40*K40 -> 196.875 | N40: CPM
B41: ANZ | C41: Social AWR | D41: LGF openers and submitters plus T3-Extended-TAL (AU + NZ) | E41: LinkedIn | F41: BOFU AI Tour web conversion (BOFU-AI) : web traffic | G41: 0.0861 | H41: 4500 | I41: 37 | J41: =I41/1000/K41 -> 8.8095238 | K41: 0.0042 | L41: =H41/I41*1000 -> 121621.62 | M41: =L41*K41 -> 510.81081 | N41: CPM
B42: ANZ | C42: Social AWR | D42: Cold lists plus seniority and function (AU + NZ) | E42: LinkedIn | F42: TOFU SIA (AWR-SI) : website visits | G42: 0.0669 | H42: 3500 | I42: 40 | J42: =I42/1000/K42 -> 11.428571 | K42: 0.0035 | L42: =H42/I42*1000 -> 87500 | M42: =L42*K42 -> 306.25 | N42: CPM
B43: ANZ | C43: Social Lead Gen | D43: Warm engagers only: image-clickers and video-viewers 365d and LGF-openers 180d; cold company list removed (AU + NZ) | E43: LinkedIn | F43: BOFU Workshop Sign-up SIA with LGF (BOFU-SIA) : warm-only audience | G43: 0.0574 | H43: 3000 | I43: 45 | J43: =I43/1000/K43 -> 15 | K43: 0.003 | L43: =H43/I43*1000 -> 66666.667 | M43: =L43*K43 -> 200 | N43: CPM
B44: subtotal | H44: =SUM(H35:H43) -> 52290
B45: ASEAN : $19,870.20 (19.0% of APAC) : LinkedIn + TTD : awareness SIM 60 / RoA 40 approved, consideration combined across all 6 | G45: Regional total → | H45: 19870.2
B46: ASEAN-SIM | C46: Programmatic AWR | D46: Decision-makers at SIM TAL accounts (SG, MY, ID) | E46: TTD | F46: TAL : B2Beacon ABM, seniority and industry baked in on the Bombora push | G46: 0.0906 | H46: 1800 | I46: 14 | J46: =I46/1000/K46 -> 20 | K46: 0.0007 | L46: =H46/I46*1000 -> 128571.43 | M46: =L46*K46 -> 90 | N46: CPM
...

Sheet JP Activation Plan
B2: Client | C2: Cloudflare
B3: Campaign | C3: Q3 FY26 Core Demand Generation : Japan
B4: Quarter | C4: Q3 FY26
B5: Start date | C5: 2026-07-01
B6: End date | C6: 2026-09-30
B7: Duration (days) | C7: cl
B8: JP budget | C8: $11,620.00
B9: Key change | C9: LINE replaced by YouTube via Google Ads, built as one Demand Gen campaign with channel controls set to YouTube only. Targeting is rebuilt on Google-native tools because YouTube accepts no Bombora or third-party audience on any platform, including DV360. Native lead form on mobile and tablet, awareness on desktop via Floodlight. Floodlight retargeting carries the lead-gen weight.
B11: REGIONAL BUDGET SUMMARY (JP)
B12: GEO | C12: % of JP | D12: Programmatic (TTD) | E12: Social Awareness (LinkedIn) | F12: Lead Gen (YouTube) | G12: Total | H12: Channels in scope
B13: Japan | C13: 1 | D13: 4067 | E13: 0 | F13: 7553 | G13: =SUM(D13:F13) -> 11620 | H13: TTD + YouTube (Google Ads, Demand Gen)
B15: PROGRAM SCHEDULE : JAPAN
B16: GEO | C16: Phase | D16: Audience | E16: Platform | F16: Targeting | G16: Weight | H16: Budget USD | I16: CPM | J16: CPC | K16: CTR | L16: Impressions | M16: Clicks | N16: Cost Type
B17: Japan : $11,620 | YouTube via Google Ads (Demand Gen) | TTD continues for reach | G17: Regional total → | H17: 11620
B18: Japan | C18: Programmatic AWR | D18: JP enterprise TAL accounts, IT and security DMs | E18: TTD | F18: TAL : Bombora B2Beacon company list + seniority + job function | G18: 0.11 | H18: 1300 | I18: 14 | J18: =I18/1000/K18 -> 20 | K18: 0.0007 | L18: =H18/I18*1000 -> 92857.143 | M18: =L18*K18 -> 65 | N18: CPM
B19: Japan | C19: Programmatic AWR | D19: JP business and tech inventory + IT/security DMs | E19: TTD | F19: Whitelist + 3PA : curated JP publisher whitelist (Bloomberg CTV, Nikkei Business) + 3PA IT/security DMs (seniority + function) | G19: 0.1 | H19: 1140 | I19: 12 | J19: =I19/1000/K19 -> 20 | K19: 0.0006 | L19: =H19/I19*1000 -> 95000 | M19: =L19*K19 -> 57 | N19: CPM
B20: Japan | C20: Programmatic RTG | D20: Site visitors, no additional filters (Japan) | E20: TTD | F20: RTG : Universal Pixel site-visit pool, web conversions | G20: 0.14 | H20: 1627 | I20: 10 | J20: =I20/1000/K20 -> 5.8823529 | K20: 0.0017 | L20: =H20/I20*1000 -> 162700 | M20: =L20*K20 -> 276.59 | N20: CPM
B21: Japan | C21: Lead gen | D21: Infrastructure-intent searchers + TAL accounts (JP) | E21: Google Ads (YouTube) | F21: Custom Segments (DDoS, CDN, Zero Trust, WAF, edge) + Customer Match for TAL accounts. Demand Gen, lead form on mobile, awareness on desktop | G21: 0.15 | H21: 1743 | I21: 12 | J21: =I21/1000/K21 -> 3 | K21: 0.004 | L21: =H21/I21*1000 -> 145250 | M21: =L21*K21 -> 581 | N21: CPM
B22: Japan | C22: Lead gen | D22: DM personas by interest and category research (JP) | E22: Google Ads (YouTube) | F22: Affinity + In-market (Network Security, Cloud Services). Demand Gen, lead form on mobile, awareness on desktop | G22: 0.15 | H22: 1743 | I22: 11 | J22: =I22/1000/K22 -> 3.1428571 | K22: 0.0035 | L22: =H22/I22*1000 -> 158454.55 | M22: =L22*K22 -> 554.59091 | N22: CPM
B23: Japan | C23: Lead gen | D23: Site visitors past 180 days (JP) | E23: Google Ads (YouTube) | F23: Floodlight retargeting (JP visitors 180d), Demand Gen ad group, carries the lead-gen weight | G23: 0.35 | H23: 4067 | I23: 10 | J23: =I23/1000/K23 -> 2.2222222 | K23: 0.0045 | L23: =H23/I23*1000 -> 406700 | M23: =L23*K23 -> 1830.15 | N23: CPM
B24: JP subtotal | H24: =SUM(H18:H23) -> 11620
B26: ALTERNATIVE CHANNEL CONSIDERATIONS FOR JAPAN
B28: YouTube via Google Ads (selected) | C28: One Demand Gen campaign, channel controls set to YouTube only (in-stream, in-feed, Shorts), off Gmail, Discover and the Display Network. Google-native targeting (Custom Segments, Customer Match, Affinity and In-market, Floodlight retargeting) because YouTube accepts no Bombora or third-party audience on any platform, including DV360. Native lead form on mobile and tablet, where the bulk of Japan watches; desktop has no form and drives to the JP landing page as awareness, captured via Floodlight. Chosen over DV360 because Google Ads gives the native lead form and Google-native targeting DV360 cannot, on the same YouTube inventory.
B29: Yahoo! Japan Ads | C29: Largest reach platform in Japan with strong B2B audience. Display, search, and DSP capability. Considered as alternative if Google Ads onboarding lift (advertiser verification, channel access) proves too high.
B30: X Twitter Japan | C30: Active B2B audience including Japanese IT and security communities. Lead generation cards available. Considered as social-channel alternative if CF requires a social platform.
B31: Native publishers (Nikkei BizGate, ITmedia, NewsPicks) | C31: Premium B2B audience for direct buys. Higher CPMs and smaller scale. Considered for niche premium reach if needed in Q3+.
B32: LinkedIn Japan (not approved) | C32: Native LGF attribution and B2B audience density (4M+ Japanese professionals). Not approved by CF team for Q3 Japan media.
B33: LINE (removed from Q3) | C33: Q2 delivered 5.71M impressions and 39,053 clicks at 88% pacing but Zaraz incompatibility meant no attribution path. Removed from Q3 to redirect spend to a trackable channel.

Sheet Platform Allocation
B2: Platform Allocation Summary
B3: Actual platform-level spend. Reconciles to total budget but cuts the view by platform rather than channel bucket.
B5: APAC : Platform Allocation
B6: Platform | D6: Budget USD | E6: % of APAC | F6: In-scope GEOs
B7: LinkedIn | D7: 61022.44 | E7: =D7/$D$10 -> 0.5835001 | F7: ANZ, ASEAN (SIM + RoA), SAARC India, GCR-HK
B8: TTD | D8: 43557.56 | E8: =D8/$D$10 -> 0.4164999 | F8: All programmatic, incl CN, TW and KR (TTD-only) and a retargeting line in every market
B9: Reddit | D9: 0 | E9: =D9/$D$10 -> 0 | F9: Dropped in Q3 (K2). Its ANZ budget moved to LinkedIn lead gen
B10: APAC TOTAL | D10: =SUM(D7:D9) -> 104580 | E10: =SUM(E7:E9) -> 1
B12: Japan : Platform Allocation
B13: Platform | D13: Budget USD | E13: % of JP | F13: In-scope
B14: Google Ads (YouTube) | D14: 7553 | E14: 0.65 | F14: Japan (YouTube via Google Ads, Demand Gen)
B15: TTD | D15: 4067 | E15: 0.35 | F15: Japan
B16: JP TOTAL | D16: 11620 | E16: 1
B18: Program total (APAC + JP)
B19: Platform | D19: Budget USD | E19: % of Total
B20: LinkedIn | D20: 61022.44 | E20: =D20/$D$24 -> 0.52515009
B21: TTD | D21: 47624.56 | E21: =D21/$D$24 -> 0.40984991
B22: Reddit | D22: 0 | E22: =D22/$D$24 -> 0
B23: Google Ads (YouTube) | D23: 7553 | E23: =D23/$D$24 -> 0.065
B24: TOTAL | D24: =SUM(D20:D23) -> 116200 | E24: =SUM(E20:E23) -> 1
B26: Why TTD is the largest platform
B27: TTD carries $43,558 of APAC because CN, TW and KR run TTD-only (no social platform in those markets) and because every market now has a dedicated TTD retargeting line. LinkedIn carries $61,022 across ANZ, ASEAN, India and HK. Reddit is dropped. The summary tables on the Activation Plan sheets show budget through the channel buckets; this sheet shows the same dollars by platform.
B29: TTD reconciliation by market type
B30: GEO | C30: Source | D30: Amount | F30: Note
B31: ANZ, ASEAN, India, HK | C31: TTD within social markets | D31: 28916.36 | F31: B2Beacon, whitelist + 3PA and a retargeting line in each
B32: CN, TW, KR | C32: TTD-only markets | D32: 14641.2 | F32: Full market budget on TTD, no social platform in scope
B33: APAC TTD TOTAL | D33: =D31+D32 -> 43557.56 | F33: Matches APAC TTD above
